[2025-05-11 17:36:45,393] [INFO] [<frozen importlib] - Starting XGBoost model training
[2025-05-11 17:36:45,393] [INFO] [<frozen importlib] - Loading data from Data/processed/splits/train.parquet
[2025-05-11 17:36:45,847] [INFO] [<frozen importlib] - Loading data from Data/processed/splits/val.parquet
[2025-05-11 17:36:45,945] [INFO] [<frozen importlib] - Calculated scale_pos_weight: 12.80
[2025-05-11 17:36:45,945] [INFO] [<frozen importlib] - Training model with early stopping
[2025-05-11 17:36:45,945] [ERROR] [<frozen importlib] - Error in XGBoost training pipeline: XGBClassifier.fit() got an unexpected keyword argument 'callbacks'
Traceback (most recent call last):
  File "/home/wanting/energy_anomaly_detection/src/training/xgboost_model.py", line 156, in main
    detector.train()
  File "/home/wanting/energy_anomaly_detection/src/training/xgboost_model.py", line 69, in train
    self.model.fit(
  File "/home/wanting/energy_anomaly_detection/.venv/lib/python3.12/site-packages/xgboost/core.py", line 729, in inner_f
    return func(**kwargs)
           ^^^^^^^^^^^^^^
TypeError: XGBClassifier.fit() got an unexpected keyword argument 'callbacks'
